Workbook
Name \0: #REF!
Name \P: #REF!
Name _19RE03: #REF!
Name _DAt: [1]Hoja1!#REF!
Name _DAT1: #REF!
Name _DAT10: [1]Hoja1!#REF!
Name _DAT11: [1]Hoja1!#REF!
Name _DAt111: [1]Hoja1!#REF!
Name _DAT12: [1]Hoja1!#REF!
Name _DAT13: [1]Hoja1!#REF!
Name _DAT14: [1]Hoja1!#REF!
Name _DAT15: [1]Hoja1!#REF!
Name _DAT16: [1]Hoja1!#REF!
Name _DAT17: [1]Hoja1!#REF!
Name _DAT18: [1]Hoja1!#REF!
Name _DAT19: [1]Hoja1!#REF!
Name _DAT2: #REF!
Name _DAT20: [1]Hoja1!#REF!
Name _DAT21: #REF!
Name _DAT22: #REF!
Name _DAT3: #REF!
Name _DAT4: #REF!
Name _DAT5: #REF!
Name _DAT6: #REF!
Name _DAT7: #REF!
Name _DAT8: #REF!
Name _DAT9: #REF!
Name _DAT91: #REF!
Name _DAT92: #REF!
Name _DAT93: #REF!
Name _DATTT: #REF!
Name _DATxx: [1]Hoja1!#REF!
Name _DATZZ: #REF!
Name _my03: #REF!
Name A_impresión_IM: #REF!
Name actioncostred: [2]Directions_Expectations!$Q$104:$Q$107
Name actionsta: [2]Directions_Expectations!$Q$104:$Q$108
Name aeriefeedrate: #REF!
Name autotrac: #REF!
Name bpu: #REF!
Name CALIDAD: [3]SupplierList!$K$3:$K$5
Name cambio: #REF!
Name Category2: '[4]Drill down'!$B$2:$B$5
Name complex: #REF!
Name Confidence1: '[4]Drill down'!$B$17:$B$21
Name confidencedesign: [2]Directions_Expectations!$Q$94:$Q$100
Name Cost: #REF!
Name critical: [2]Directions_Expectations!$Q$48:$Q$49
Name DAT_BIS: #REF!
Name DAT10_BIS: #REF!
Name DAT11_BIS: #REF!
Name DAT12_BIS: #REF!
Name DAT13_BIS: #REF!
Name DAT14_BIS: #REF!
Name DAT15_BIS: #REF!
Name DAT16_BIS: #REF!
Name DAT17_BIS: #REF!
Name DAT18_BIS: #REF!
Name DAT19_BIS: #REF!
Name DAT2_BIS: #REF!

Sheet R120638-A
A2: REFERENCIA | B2: R120638 | C2: SECUENCIA DE EVENTOS | D2: Min. Std "D" | F2: =SUMIF(D16:D102,"D",N16:N102) -> 2.0259251 | G2: Min. Std "D"(P&F)/1,3 | I2: =SUMIF(D16:D102,"D",O16:O102)/1.3 -> 1.5565413 | J2: Ciclos posibles | L2: =480/I4 -> 183.44828 | M2: P&Fi | O2: =((F2+F3)/1.3-(I2+I3))*MIN(L2:L3) -> 2.2169535 | P2: Nº piezas autonomía
A3: CELULA | B3: 142A | D3: Min. Std "R" | F3: =SUMIF(D16:D102,"R",N16:N102) -> 0.13205418 | G3: Min. Std "R"(P&F)/1,3 | I3: =SUMIF(D16:D102,"R",O16:O102)/1.3 -> 0.091357816 | J3: Ciclos posibles Hombre | L3: =480/(F2/1.3+F3/1.3)/1.06 -> 272.79189 | M3: Piezas | O3: =IF((480-L4)<O2,L3,L2) -> 183.44828
A4: MC | B4: =SUMIF(D16:D83,"MC",N16:N83) -> 1.06 | D4: Ida | F4: =IF(1.1*(B4*1.08-F3/1.3)<0,0,1.1*(B4*1.08-F3/1.3)) -> 1.1475418 | G4: C.W | I4: =IF(F4=0,(F2/1.3+F3/1.3)*1.06,B4+I2) -> 2.6165413 | J4: Min.de trabajo manual | L4: =(I2+I3)*MIN(L2:L3)*1.06 -> 320.44252 | M4: Std | O4: =8*1.397*100/O3 -> 6.0921804 | P4: 45
C6: Carga | D6: =SUMIFS($O$15:$O$90,$P$15:$P$90,C6) -> 0 | E6: =+D6*$O$3 -> 0
C7: Traslados. | D7: =SUMIFS($O$15:$O$90,$P$15:$P$90,C7) -> 0.014260606 | E7: =+D7*$O$3 -> 2.6160836
C8: Verificación | D8: =SUMIFS($O$15:$O$90,$P$15:$P$90,C8) -> 0.012543636 | E8: =+D8*$O$3 -> 2.3011085
C9: Descarga | D9: =SUMIFS($O$15:$O$90,$P$15:$P$90,C9) -> 0.068425 | E9: =+D9*$O$3 -> 12.552448
C10: Limpieza | D10: =SUMIFS($O$15:$O$90,$P$15:$P$90,C10) -> 0.00354875 | E10: =+D10*$O$3 -> 0.65101207
C11: Cambio de carga | D11: =SUMIFS($O$15:$O$90,$P$15:$P$90,C11) -> 0.017692737 | E11: =+D11*$O$3 -> 3.2457021
C12: Grafico | D12: =SUMIFS($O$15:$O$90,$P$15:$P$90,C12) -> 0.0058431818 | E12: =+D12*$O$3 -> 1.0719216
C13: CH | D13: =SUMIFS($O$15:$O$90,$P$15:$P$90,C13) -> 2.019955 | E13: =+D13*$O$3 -> 370.55726
A15: MAQUINA | B15: Nº | C15: ELEMENTO | D15: TIPO | E15: T1 | F15: T2 | G15: T3 | H15: T4 | I15: T5 | J15: AC | K15: P&F | L15: MINUTOS STD | M15: OCURRENCIA | N15: MIN STD/CICLO | O15: MIN STD/CICLO (P&F) | P15: DESCRIPCIÓN
A16: TORNO | B16: 1 | C16: TORNEAR | D16: M | E16: 90 | J16: 100 | K16: 1 | L16: =(AVERAGEA(E16:I16)/100)*(J16/100)*(K16) -> 0.9 | M16: 1 | N16: =+L16*M16 -> 0.9 | O16: =+N16/K16 -> 0.9 | P16: Tiempo de máquina
A17: TORNO | B17: 2 | C17: CH.-Abrir puertas y desplazar torreta a posición de trabajo | D17: D | E17: 92 | J17: 100 | K17: 1.1 | L17: =(AVERAGEA(E17:I17)/100)*(J17/100)*(K17) -> 1.012 | M17: 0.0005 | N17: =+L17*M17 -> 0.000506 | O17: =+N17/K17 -> 0.00046 | P17: CH
A18: TORNO | B18: 3 | C18: CH.-Cambio (12) herramientas 2º cabezal, soplando herramienta y gitando torreta. | D18: D | E18: 930 | J18: 100 | K18: 1.1 | L18: =(AVERAGEA(E18:I18)/100)*(J18/100)*(K18) -> 10.23 | M18: 0.0005 | N18: =+L18*M18 -> 0.005115 | O18: =+N18/K18 -> 0.00465 | P18: CH
A19: TORNO | B19: 4 | C19: CH.- Cambio (12) herramientas 1º cabezal, soplando herramienta y girando torreta. | D19: D | E19: 678 | J19: 100 | K19: 1.1 | L19: =(AVERAGEA(E19:I19)/100)*(J19/100)*(K19) -> 7.458 | M19: 0.0005 | N19: =+L19*M19 -> 0.003729 | O19: =+N19/K19 -> 0.00339 | P19: CH
A20: TORNO | B20: 5 | C20: CH.- Posicionar cabezales, cerrar puertas e iniciar programa de medición. | D20: D | E20: 70 | J20: 130 | K20: 1.1 | L20: =(AVERAGEA(E20:I20)/100)*(J20/100)*(K20) -> 1.001 | M20: 0.0005 | N20: =+L20*M20 -> 0.0005005 | O20: =+N20/K20 -> 0.000455 | P20: CH
A21: TORNO | B21: 6 | C21: CH.-Medición de herramientas. | D21: D | E21: 250 | J21: 100 | K21: 1.1 | L21: =(AVERAGEA(E21:I21)/100)*(J21/100)*(K21) -> 2.75 | M21: 0.0005 | N21: =+L21*M21 -> 0.001375 | O21: =+N21/K21 -> 0.00125 | P21: CH
A22: TORNO | B22: 7 | C22: CH.- Hacer pieza y medir hasta corregir, | D22: D | E22: 780 | J22: 100 | K22: 1.1 | L22: =(AVERAGEA(E22:I22)/100)*(J22/100)*(K22) -> 8.58 | M22: 0.0005 | N22: =+L22*M22 -> 0.00429 | O22: =+N22/K22 -> 0.0039 | P22: CH
A23: TORNO | B23: 8 | C23: CH.- Llenado de cinta de paso torno-talladora. | D23: D | E23: 1105 | J23: 100 | K23: 1.1 | L23: =(AVERAGEA(E23:I23)/100)*(J23/100)*(K23) -> 12.155 | M23: 0.0005 | N23: =+L23*M23 -> 0.0060775 | O23: =+N23/K23 -> 0.005525 | P23: CH
A24: TORNO | B24: 9 | C24: CH.-Rearmar talladora. | D24: D | E24: 50 | J24: 130 | K24: 1.1 | L24: =(AVERAGEA(E24:I24)/100)*(J24/100)*(K24) -> 0.715 | M24: 0.0005 | N24: =+L24*M24 -> 0.0003575 | O24: =+N24/K24 -> 0.000325 | P24: CH
A25: TORNO | B25: 10 | C25: Medir pieza en inicio de turno. MEDICIÓN=0,691 | D25: R | E25: 63.090909 | J25: 100 | K25: 1.1 | L25: =(AVERAGEA(E25:I25)/100)*(J25/100)*(K25) -> 0.694 | M25: 0.0025 | N25: =+L25*M25 -> 0.001735 | O25: =+N25/K25 -> 0.0015772727 | P25: Verificación
A26: TALLADORA | B26: 11 | C26: TALLAR | D26: M | E26: 95 | J26: 100 | K26: 1 | L26: =(AVERAGEA(E26:I26)/100)*(J26/100)*(K26) -> 0.95 | M26: 1 | N26: =+L26*M26 -> 0.95 | O26: =+N26/K26 -> 0.95 | P26: Tiempo de máquina
A27: TALLADORA | B27: 12 | C27: Soplar con manguera de aire pieza a verificar. | D27: R | E27: 13 | F27: 15 | G27: 17 | H27: 17 | I27: 18 | J27: 105 | K27: 1.1 | L27: =(AVERAGEA(E27:I27)/100)*(J27/100)*(K27) -> 0.1848 | M27: 0.005 | N27: =+L27*M27 -> 0.000924 | O27: =+N27/K27 -> 0.00084 | P27: Verificación
A28: TALLADORA | B28: 13 | C28: Tol. Verificar con micro de platillos. 36,07-36,04. F-72=,114+,072=,186 | D28: R | E28: 16.909091 | J28: 100 | K28: 1.1 | L28: =(AVERAGEA(E28:I28)/100)*(J28/100)*(K28) -> 0.186 | M28: 0.005 | N28: =+L28*M28 -> 0.00093 | O28: =+N28/K28 -> 0.00084545455 | P28: Verificación
A29: MARCADORA | B29: 14 | C29: MARCAR | D29: M | E29: 50 | J29: 100 | K29: 1 | L29: =(AVERAGEA(E29:I29)/100)*(J29/100)*(K29) -> 0.5 | M29: 1 | N29: =+L29*M29 -> 0.5 | O29: =+N29/K29 -> 0.5 | P29: Tiempo de máquina
A30: AFEITADORA | B30: 15 | C30: AFEITAR | D30: MC | E30: 106 | J30: 100 | K30: 1 | L30: =(AVERAGEA(E30:I30)/100)*(J30/100)*(K30) -> 1.06 | M30: 1 | N30: =+L30*M30 -> 1.06 | O30: =+N30/K30 -> 1.06 | P30: Tiempo de máquina
A31: AFEITADORA | B31: 16 | C31: Soplar con manguera de aire pieza a verificar. | D31: R | E31: 13 | F31: 15 | G31: 17 | H31: 17 | I31: 18 | J31: 105 | K31: 1.1 | L31: =(AVERAGEA(E31:I31)/100)*(J31/100)*(K31) -> 0.1848 | M31: 0.005 | N31: =+L31*M31 -> 0.000924 | O31: =+N31/K31 -> 0.00084 | P31: Verificación
A32: AFEITADORA | B32: 17 | C32: Tol. Verificar con micro de platillos. 36,00-35,97. F-72=,114+,072=,186 | D32: R | E32: 16.909091 | J32: 100 | K32: 1.1 | L32: =(AVERAGEA(E32:I32)/100)*(J32/100)*(K32) -> 0.186 | M32: 0.005 | N32: =+L32*M32 -> 0.00093 | O32: =+N32/K32 -> 0.00084545455 | P32: Verificación
A33: AFEITADORA | B33: 18 | C33: Tol. Verificar visual rebaba y chaflan | D33: R | E33: 16.909091 | J33: 100 | K33: 1.1 | L33: =(AVERAGEA(E33:I33)/100)*(J33/100)*(K33) -> 0.186 | M33: 0.005 | N33: =+L33*M33 -> 0.00093 | O33: =+N33/K33 -> 0.00084545455 | P33: Verificación
A34: AFEITADORA | B34: 19 | C34: Tol. Verificación visual de referencia. | D34: R | E34: 6 | J34: 100 | K34: 1.1 | L34: =(AVERAGEA(E34:I34)/100)*(J34/100)*(K34) -> 0.066 | M34: 0.005 | N34: =+L34*M34 -> 0.00033 | O34: =+N34/K34 -> 0.0003 | P34: Verificación
A35: CELULA | B35: 20 | C35: Descargar piezas de carril de afeitadora a percha. | D35: R | E35: 357 | J35: 115 | K35: 1.12 | L35: =(AVERAGEA(E35:I35)/100)*(J35/100)*(K35) -> 4.59816 | M35: 0.016666667 | N35: =+L35*M35 -> 0.076636 | O35: =+N35/K35 -> 0.068425 | P35: Descarga
A36: AFEITADORA | B36: 21 | C36: Posicionarse vacio en bandeja de piezas sin procesar. 10m G958=0,166 | D36: R | E36: 15.090909 | J36: 100 | K36: 1.1 | L36: =(AVERAGEA(E36:I36)/100)*(J36/100)*(K36) -> 0.166 | M36: 0.016666667 | N36: =+L36*M36 -> 0.0027666667 | O36: =+N36/K36 -> 0.0025151515 | P36: Traslados.
A37: VARIOS | B37: 22 | C37: Traslado a zona de trabajo, según porceda. (20m G-982= 0,323) | D37: R | E37: 29.363636 | J37: 100 | K37: 1.1 | L37: =(AVERAGEA(E37:I37)/100)*(J37/100)*(K37) -> 0.323 | M37: 0.04 | N37: =+L37*M37 -> 0.01292 | O37: =+N37/K37 -> 0.011745455 | P37: Traslados.
A38: CELULA | B38: 23 | C38: Limpiar virutas de torno con manguera de aire y gancho. | D38: D | E38: 56 | F38: 63 | G38: 49 | J38: 120 | K38: 1.12 | L38: =(AVERAGEA(E38:I38)/100)*(J38/100)*(K38) -> 0.75264 | M38: 0.0025 | N38: =+L38*M38 -> 0.0018816 | O38: =+N38/K38 -> 0.00168 | P38: Limpieza
A39: CELULA | B39: 24 | C39: Limpiar virutas de talladora con manguera de aire. | D39: D | E39: 65 | J39: 115 | K39: 1.12 | L39: =(AVERAGEA(E39:I39)/100)*(J39/100)*(K39) -> 0.8372 | M39: 0.0025 | N39: =+L39*M39 -> 0.002093 | O39: =+N39/K39 -> 0.00186875 | P39: Limpieza
A40: VARIOS | B40: 25 | C40: Girar bandeja de piezas 180º | D40: R | E40: 25 | F40: 25 | J40: 80 | K40: 1.1 | L40: =(AVERAGEA(E40:I40)/100)*(J40/100)*(K40) -> 0.22 | M40: 0.0026041667 | N40: =+L40*M40 -> 0.00057291667 | O40: =+N40/K40 -> 0.00052083333 | P40: Cambio de carga
A41: BIN PICKING | B41: 26 | C41: Cambio de carga bandejas PSP | D41: R | E41: 516 | J41: 100 | K41: 1.1 | L41: =(AVERAGEA(E41:I41)/100)*(J41/100)*(K41) -> 5.676 | M41: 0.0018315018 | N41: =+L41*M41 -> 0.010395604 | O41: =+N41/K41 -> 0.0094505495 | P41: Cambio de carga
A42: CELULA | B42: 27 | C42: Cambio de carga bandejas PP | D42: R | E42: 593 | J42: 100 | K42: 1.1 | L42: =(AVERAGEA(E42:I42)/100)*(J42/100)*(K42) -> 6.523 | M42: 0.0013020833 | N42: =+L42*M42 -> 0.0084934896 | O42: =+N42/K42 -> 0.0077213542 | P42: Cambio de carga
A43: VARIOS | B43: 28 | C43: Cumplementar parametros de control de calidad de forma manual.(1) | D43: R | E43: 40 | J43: 100 | K43: 1.1 | L43: =(AVERAGEA(E43:I43)/100)*(J43/100)*(K43) -> 0.44 | M43: 0.01 | N43: =+L43*M43 -> 0.0044 | O43: =+N43/K43 -> 0.004 | P43: Verificación
...

Sheet R120636-B
A2: REFERENCIA | B2: R120636 | C2: SECUENCIA DE EVENTOS | D2: Min. Std "D" | F2: =SUMIF(D16:D110,"D",N16:N110) -> 2.0194901 | G2: Min. Std "D"(P&F)/1,3 | I2: =SUMIF(D16:D110,"D",O16:O110)/1.3 -> 1.5520413 | J2: Ciclos posibles | L2: =480/I4 -> 188.08473 | M2: P&Fi | O2: =((F2+F3)/1.3-(I2+I3))*MIN(L2:L3) -> 2.2303083 | P2: Nº piezas autonomía
A3: CELULA | B3: 142B | D3: Min. Std "R" | F3: =SUMIF(D16:D110,"R",N16:N110) -> 0.13410452 | G3: Min. Std "R"(P&F)/1,3 | I3: =SUMIF(D16:D110,"R",O16:O110)/1.3 -> 0.0927119 | J3: Ciclos posibles Hombre | L3: =480/(F2/1.3+F3/1.3)/1.06 -> 273.34729 | M3: Piezas | O3: =IF((480-L4)<O2,L3,L2) -> 188.08473
A4: MC | B4: =SUMIF(D16:D91,"MC",N16:N91) -> 1 | D4: Ida | F4: =IF(1.1*(B4*1.08-F3/1.3)<0,0,1.1*(B4*1.08-F3/1.3)) -> 1.0745269 | G4: C.W | I4: =IF(F4=0,(F2/1.3+F3/1.3)*1.06,B4+I2) -> 2.5520413 | J4: Min.de trabajo manual | L4: =(I2+I3)*MIN(L2:L3)*1.06 -> 327.91414 | M4: Std | O4: =8*1.397*100/O3 -> 5.9420029 | P4: 49
C6: Carga | D6: =SUMIFS($O$15:$O$98,$P$15:$P$98,C6) -> 0 | E6: =+D6*$O$3 -> 0
C7: Traslados. | D7: =SUMIFS($O$15:$O$98,$P$15:$P$98,C7) -> 0.016775758 | E7: =+D7*$O$3 -> 3.1552638
C8: Verificación | D8: =SUMIFS($O$15:$O$98,$P$15:$P$98,C8) -> 0.0088045455 | E8: =+D8*$O$3 -> 1.6560005
C9: Descarga | D9: =SUMIFS($O$15:$O$98,$P$15:$P$98,C9) -> 0.0714 | E9: =+D9*$O$3 -> 13.42925
C10: Limpieza | D10: =SUMIFS($O$15:$O$98,$P$15:$P$98,C10) -> 0.00354875 | E10: =+D10*$O$3 -> 0.66746568
C11: Cambio de carga | D11: =SUMIFS($O$15:$O$98,$P$15:$P$98,C11) -> 0.017701986 | E11: =+D11*$O$3 -> 3.3294731
C12: Grafico | D12: =SUMIFS($O$15:$O$98,$P$15:$P$98,C12) -> 0.0058431818 | E12: =+D12*$O$3 -> 1.0990133
C13: CH | D13: =SUMIFS($O$15:$O$98,$P$15:$P$98,C13) -> 2.014105 | E13: =+D13*$O$3 -> 378.82239
A15: MAQUINA | B15: Nº | C15: ELEMENTO | D15: TIPO | E15: T1 | F15: T2 | G15: T3 | H15: T4 | I15: T5 | J15: AC | K15: P&F | L15: MINUTOS STD | M15: OCURRENCIA | N15: MIN STD/CICLO | O15: MIN STD/CICLO (P&F) | P15: DESCRIPCIÓN
A16: TORNO | B16: 1 | C16: TORNEAR | D16: M | E16: 64 | J16: 100 | K16: 1 | L16: =(AVERAGEA(E16:I16)/100)*(J16/100)*(K16) -> 0.64 | M16: 1 | N16: =+L16*M16 -> 0.64 | O16: =+N16/K16 -> 0.64 | P16: Tiempo de máquina
A17: TORNO | B17: 2 | C17: Posicionarse vacio en zona de descarga de afeitadora. | D17: R | E17: 15.090909 | J17: 100 | K17: 1.1 | L17: =(AVERAGEA(E17:I17)/100)*(J17/100)*(K17) -> 0.166 | M17: 0.016666667 | N17: =+L17*M17 -> 0.0027666667 | O17: =+N17/K17 -> 0.0025151515 | P17: Traslados.
A18: TORNO | B18: 3 | C18: Soplar con manguera de aire pieza a verificar. | D18: R | E18: 13 | F18: 15 | G18: 17 | H18: 17 | I18: 18 | J18: 105 | K18: 1.1 | L18: =(AVERAGEA(E18:I18)/100)*(J18/100)*(K18) -> 0.1848 | M18: 0.0025 | N18: =+L18*M18 -> 0.000462 | O18: =+N18/K18 -> 0.00042 | P18: Verificación
A19: TORNO | B19: 4 | C19: Tol. Verificar con calibre de herradura. Ø 90,15 ± 0,10 F 14=0,081+0,046=0,127 | D19: R | E19: 11.545455 | J19: 100 | K19: 1.1 | L19: =(AVERAGEA(E19:I19)/100)*(J19/100)*(K19) -> 0.127 | M19: 0.0025 | N19: =+L19*M19 -> 0.0003175 | O19: =+N19/K19 -> 0.00028863636 | P19: Verificación
A20: TORNO | B20: 5 | C20: Tol. Verificar galga distancia 32 ± 0,2 y 16 ± 0,05 | D20: R | E20: 27 | F20: 27 | J20: 100 | K20: 1.12 | L20: =(AVERAGEA(E20:I20)/100)*(J20/100)*(K20) -> 0.3024 | M20: 0.0025 | N20: =+L20*M20 -> 0.000756 | O20: =+N20/K20 -> 0.000675 | P20: Verificación
A21: TORNO | B21: 6 | C21: Tol. Verificar Salto entre caras. máximo 0,03 | D21: R | E21: 25 | F21: 25 | J21: 100 | K21: 1.12 | L21: =(AVERAGEA(E21:I21)/100)*(J21/100)*(K21) -> 0.28 | M21: 0.0025 | N21: =+L21*M21 -> 0.0007 | O21: =+N21/K21 -> 0.000625 | P21: Verificación
A22: TORNO | B22: 7 | C22: Tol. Verificar calibre distancia 15 ± 0,05 | D22: R | E22: 27 | F22: 27 | J22: 100 | K22: 1.12 | L22: =(AVERAGEA(E22:I22)/100)*(J22/100)*(K22) -> 0.3024 | M22: 0.0025 | N22: =+L22*M22 -> 0.000756 | O22: =+N22/K22 -> 0.000675 | P22: Verificación
A23: TORNO | B23: 8 | C23: Tol. Verificar Calibre cota (S) 13,50 ± 0,13 | D23: R | E23: 12 | F23: 18 | J23: 100 | K23: 1.12 | L23: =(AVERAGEA(E23:I23)/100)*(J23/100)*(K23) -> 0.168 | M23: 0.0025 | N23: =+L23*M23 -> 0.00042 | O23: =+N23/K23 -> 0.000375 | P23: Verificación
A24: TORNO | B24: 9 | C24: Tol. Verificar Calibre cono (S) 7º 9' 10'' ± 0,4º (±0,06 mm en el reloj) | D24: R | E24: 12 | F24: 18 | J24: 100 | K24: 1.12 | L24: =(AVERAGEA(E24:I24)/100)*(J24/100)*(K24) -> 0.168 | M24: 0.0025 | N24: =+L24*M24 -> 0.00042 | O24: =+N24/K24 -> 0.000375 | P24: Verificación
A25: TALLADORA | B25: 10 | C25: TALLAR | D25: M | E25: 80 | J25: 100 | K25: 1 | L25: =(AVERAGEA(E25:I25)/100)*(J25/100)*(K25) -> 0.8 | M25: 1 | N25: =+L25*M25 -> 0.8 | O25: =+N25/K25 -> 0.8 | P25: Tiempo de máquina
A26: TALLADORA | B26: 11 | C26: Soplar con manguera de aire pieza a verificar. | D26: R | E26: 13 | F26: 15 | G26: 17 | H26: 17 | I26: 18 | J26: 105 | K26: 1.1 | L26: =(AVERAGEA(E26:I26)/100)*(J26/100)*(K26) -> 0.1848 | M26: 0.005 | N26: =+L26*M26 -> 0.000924 | O26: =+N26/K26 -> 0.00084 | P26: Verificación
A27: TALLADORA | B27: 12 | C27: Tol. Verificar micro de platillos. 36,57-36,60 | D27: R | E27: 16.909091 | J27: 100 | K27: 1.1 | L27: =(AVERAGEA(E27:I27)/100)*(J27/100)*(K27) -> 0.186 | M27: 0.005 | N27: =+L27*M27 -> 0.00093 | O27: =+N27/K27 -> 0.00084545455 | P27: Verificación
A28: REBERBADORA | B28: 13 | C28: REBARBADORA | D28: M | E28: 5 | J28: 100 | K28: 1 | L28: =(AVERAGEA(E28:I28)/100)*(J28/100)*(K28) -> 0.05 | M28: 1 | N28: =+L28*M28 -> 0.05 | O28: =+N28/K28 -> 0.05 | P28: Tiempo de máquina
A29: AFEITADORA | B29: 14 | C29: AFEITAR | D29: MC | E29: 100 | J29: 100 | K29: 1 | L29: =(AVERAGEA(E29:I29)/100)*(J29/100)*(K29) -> 1 | M29: 1 | N29: =+L29*M29 -> 1 | O29: =+N29/K29 -> 1 | P29: Tiempo de máquina
A30: AFEITADORA | B30: 15 | C30: Soplar con manguera de aire pieza a verificar. | D30: R | E30: 13 | F30: 15 | G30: 17 | H30: 17 | I30: 18 | J30: 105 | K30: 1.1 | L30: =(AVERAGEA(E30:I30)/100)*(J30/100)*(K30) -> 0.1848 | M30: 0.005 | N30: =+L30*M30 -> 0.000924 | O30: =+N30/K30 -> 0.00084 | P30: Verificación
A31: AFEITADORA | B31: 16 | C31: Tol. Verificar micro de platillos.36,50 - 36,53 | D31: R | E31: 16.909091 | J31: 100 | K31: 1.1 | L31: =(AVERAGEA(E31:I31)/100)*(J31/100)*(K31) -> 0.186 | M31: 0.005 | N31: =+L31*M31 -> 0.00093 | O31: =+N31/K31 -> 0.00084545455 | P31: Verificación
A32: AFEITADORA | B32: 17 | C32: Tol. Verificación visual de referencia. | D32: R | E32: 6 | J32: 100 | K32: 1.1 | L32: =(AVERAGEA(E32:I32)/100)*(J32/100)*(K32) -> 0.066 | M32: 0.005 | N32: =+L32*M32 -> 0.00033 | O32: =+N32/K32 -> 0.0003 | P32: Verificación
A33: AFEITADORA | B33: 18 | C33: Tol. Verificación visual chaflanado y reberbado | D33: R | E33: 6 | J33: 100 | K33: 1.1 | L33: =(AVERAGEA(E33:I33)/100)*(J33/100)*(K33) -> 0.066 | M33: 0.005 | N33: =+L33*M33 -> 0.00033 | O33: =+N33/K33 -> 0.0003 | P33: Verificación
A34: LAVADORA | B34: 19 | C34: LAVAR | D34: M | E34: 55 | J34: 100 | K34: 1 | L34: =(AVERAGEA(E34:I34)/100)*(J34/100)*(K34) -> 0.55 | M34: 1 | N34: =+L34*M34 -> 0.55 | O34: =+N34/K34 -> 0.55 | P34: Tiempo de máquina
A35: CELULA | B35: 20 | C35: Descargar a percha hasta vaciar. | D35: R | E35: 357 | J35: 120 | K35: 1.12 | L35: =(AVERAGEA(E35:I35)/100)*(J35/100)*(K35) -> 4.79808 | M35: 0.016666667 | N35: =+L35*M35 -> 0.079968 | O35: =+N35/K35 -> 0.0714 | P35: Descarga
A36: LAVADORA | B36: 21 | C36: Posicionarse vacio en zona de trabajo. | D36: R | E36: 15.090909 | J36: 100 | K36: 1.1 | L36: =(AVERAGEA(E36:I36)/100)*(J36/100)*(K36) -> 0.166 | M36: 0.016666667 | N36: =+L36*M36 -> 0.0027666667 | O36: =+N36/K36 -> 0.0025151515 | P36: Traslados.
A37: VARIOS | B37: 22 | C37: Traslado a zona de trabajo, según porceda. (20m G-982= 0,323) | D37: R | E37: 29.363636 | J37: 100 | K37: 1.1 | L37: =(AVERAGEA(E37:I37)/100)*(J37/100)*(K37) -> 0.323 | M37: 0.04 | N37: =+L37*M37 -> 0.01292 | O37: =+N37/K37 -> 0.011745455 | P37: Traslados.
A38: CELULA | B38: 23 | C38: Limpiar virutas de torno con manguera de aire y gancho. | D38: D | E38: 56 | F38: 63 | G38: 49 | J38: 120 | K38: 1.12 | L38: =(AVERAGEA(E38:I38)/100)*(J38/100)*(K38) -> 0.75264 | M38: 0.0025 | N38: =+L38*M38 -> 0.0018816 | O38: =+N38/K38 -> 0.00168 | P38: Limpieza
A39: CELULA | B39: 24 | C39: Limpiar virutas de talladora con manguera de aire. | D39: D | E39: 65 | J39: 115 | K39: 1.12 | L39: =(AVERAGEA(E39:I39)/100)*(J39/100)*(K39) -> 0.8372 | M39: 0.0025 | N39: =+L39*M39 -> 0.002093 | O39: =+N39/K39 -> 0.00186875 | P39: Limpieza
A40: VARIOS | B40: 25 | C40: Girar bandeja de piezas 180º | D40: R | E40: 25 | F40: 25 | J40: 80 | K40: 1.1 | L40: =(AVERAGEA(E40:I40)/100)*(J40/100)*(K40) -> 0.22 | M40: 0.0026041667 | N40: =+L40*M40 -> 0.00057291667 | O40: =+N40/K40 -> 0.00052083333 | P40: Cambio de carga
A41: BIN PICKING | B41: 26 | C41: Cambio de carga bandejas PSP | D41: R | E41: 516.18182 | J41: 100 | K41: 1.1 | L41: =(AVERAGEA(E41:I41)/100)*(J41/100)*(K41) -> 5.678 | M41: 0.0018315018 | N41: =+L41*M41 -> 0.010399267 | O41: =+N41/K41 -> 0.0094538795 | P41: Cambio de carga
A42: CELULA | B42: 27 | C42: Cambio de carga bandejas PP | D42: R | E42: 593.45455 | J42: 100 | K42: 1.1 | L42: =(AVERAGEA(E42:I42)/100)*(J42/100)*(K42) -> 6.528 | M42: 0.0013020833 | N42: =+L42*M42 -> 0.0085 | O42: =+N42/K42 -> 0.0077272727 | P42: Cambio de carga
A43: VARIOS | B43: 28 | C43: Grabar datos registrados con pulsador. | D43: R | E43: 3 | J43: 100 | K43: 1.1 | L43: =(AVERAGEA(E43:I43)/100)*(J43/100)*(K43) -> 0.033 | M43: 0.005 | N43: =+L43*M43 -> 0.000165 | O43: =+N43/K43 -> 0.00015 | P43: Verificación
...

Sheet R544000-C
A2: REFERENCIA | B2: R544000 | C2: SECUENCIA DE EVENTOS | D2: Min. Std "D" | F2: =SUMIF(D16:D106,"D",N16:N106) -> 1.1154582 | G2: Min. Std "D"(P&F)/1,3 | I2: =SUMIF(D16:D106,"D",O16:O106)/1.3 -> 0.84954776 | J2: Ciclos posibles | L2: =480/I4 -> 269.61782 | M2: P&Fi | O2: =((F2+F3)/1.3-(I2+I3))*MIN(L2:L3) -> 5.5121223 | P2: Nº piezas autonomía
A3: CELULA | B3: 142C | D3: Min. Std "R" | F3: =SUMIF(D16:D106,"R",N16:N106) -> 0.16197157 | G3: Min. Std "R"(P&F)/1,3 | I3: =SUMIF(D16:D106,"R",O16:O106)/1.3 -> 0.11264629 | J3: Ciclos posibles Hombre | L3: =480/(F2/1.3+F3/1.3)/1.06 -> 460.83102 | M3: Piezas | O3: =IF((480-L4)<O2,L3,L2) -> 269.61782
A4: MC | B4: =SUMIF(D16:D89,"MC",N16:N89) -> 0.93075 | D4: Ida | F4: =IF(1.1*(B4*1.08-F3/1.3)<0,0,1.1*(B4*1.08-F3/1.3)) -> 0.96867814 | G4: C.W | I4: =IF(F4=0,(F2/1.3+F3/1.3)*1.06,B4+I2) -> 1.7802978 | J4: Min.de trabajo manual | L4: =(I2+I3)*MIN(L2:L3)*1.06 -> 274.99014 | M4: Std | O4: =8*1.397*100/O3 -> 4.1451266 | P4: 45
C6: Carga | D6: =SUMIFS($O$15:$O$98,$P$15:$P$98,C6) -> 0 | E6: =+D6*$O$3 -> 0
C7: Traslados. | D7: =SUMIFS($O$15:$O$98,$P$15:$P$98,C7) -> 0.022727273 | E7: =+D7*$O$3 -> 6.1276777
C8: Verificación | D8: =SUMIFS($O$15:$O$98,$P$15:$P$98,C8) -> 0.055044403 | E8: =+D8*$O$3 -> 14.840952
C9: Descarga | D9: =SUMIFS($O$15:$O$98,$P$15:$P$98,C9) -> 0.0084027778 | E9: =+D9*$O$3 -> 2.2655386
C10: Limpieza | D10: =SUMIFS($O$15:$O$98,$P$15:$P$98,C10) -> 0.05682875 | E10: =+D10*$O$3 -> 15.322044
C11: Cambio de carga | D11: =SUMIFS($O$15:$O$98,$P$15:$P$98,C11) -> 0.02889678 | E11: =+D11*$O$3 -> 7.7910869
C12: Grafico | D12: =SUMIFS($O$15:$O$98,$P$15:$P$98,C12) -> 0.007375 | E12: =+D12*$O$3 -> 1.9884314
C13: CH | D13: =SUMIFS($O$15:$O$98,$P$15:$P$98,C13) -> 1.0773273 | E13: =+D13*$O$3 -> 290.46663
A15: MAQUINA | B15: Nº | C15: ELEMENTO | D15: TIPO | E15: T1 | F15: T2 | G15: T3 | H15: T4 | I15: T5 | J15: AC | K15: P&F | L15: MINUTOS STD | M15: OCURRENCIA | N15: MIN STD/CICLO | O15: MIN STD/CICLO (P&F) | P15: DESCRIPCIÓN
A16: TORNO | B16: 1 | C16: TORNEAR | D16: MC | E16: 90 | J16: 100 | K16: 1 | L16: =(AVERAGEA(E16:I16)/100)*(J16/100)*(K16) -> 0.9 | M16: 1 | N16: =+L16*M16 -> 0.9 | O16: =+N16/K16 -> 0.9 | P16: Tiempo de máquina
A17: TORNO | B17: 2 | C17: MEDICIÓN | D17: MC | E17: 25 | J17: 100 | K17: 1 | L17: =(AVERAGEA(E17:I17)/100)*(J17/100)*(K17) -> 0.25 | M17: 0.1 | N17: =+L17*M17 -> 0.025 | O17: =+N17/K17 -> 0.025 | P17: Tiempo de máquina
A18: TORNO | B18: 3 | C18: Posicionarse en mesa para verificar. G-10 = 0,052 | D18: R | E18: 5.2 | J18: 100 | K18: 1.1 | L18: =(AVERAGEA(E18:I18)/100)*(J18/100)*(K18) -> 0.0572 | M18: 0.01 | N18: =+L18*M18 -> 0.000572 | O18: =+N18/K18 -> 0.00052 | P18: Verificación
A19: TORNO | B19: 4 | C19: Soplar con manguera de aire pieza a verificar. | D19: R | E19: 20 | F19: 24 | G19: 18 | H19: 18 | I19: 20 | J19: 105 | K19: 1.11 | L19: =(AVERAGEA(E19:I19)/100)*(J19/100)*(K19) -> 0.2331 | M19: 0.01 | N19: =+L19*M19 -> 0.002331 | O19: =+N19/K19 -> 0.0021 | P19: Verificación
A20: TORNO | B20: 5 | C20: Tol. Verificar calibre de herradura. (Diámetro exterior Ø 91,08 +- 0,05 F 30=0,120+0,06=0,180 | D20: R | E20: 18 | J20: 100 | K20: 1.1 | L20: =(AVERAGEA(E20:I20)/100)*(J20/100)*(K20) -> 0.198 | M20: 0.01 | N20: =+L20*M20 -> 0.00198 | O20: =+N20/K20 -> 0.0018 | P20: Verificación
A21: TORNO | B21: 6 | C21: Tol. Verificar diametro chaflan. 6,09 ± 0,1 | D21: R | E21: 18 | J21: 100 | K21: 1.1 | L21: =(AVERAGEA(E21:I21)/100)*(J21/100)*(K21) -> 0.198 | M21: 0.01 | N21: =+L21*M21 -> 0.00198 | O21: =+N21/K21 -> 0.0018 | P21: Verificación
A22: TORNO | B22: 7 | C22: Tol. Verificar calibre de herradura. (Anchura Ø 32,10-32,15)) | D22: R | E22: 18 | J22: 100 | K22: 1.1 | L22: =(AVERAGEA(E22:I22)/100)*(J22/100)*(K22) -> 0.198 | M22: 0.01 | N22: =+L22*M22 -> 0.00198 | O22: =+N22/K22 -> 0.0018 | P22: Verificación
A23: TORNO | B23: 8 | C23: Tol. Verificar alexómetro (Diámetro interior Ø 56,06 (+0,07 / +0,05)) | D23: R | E23: 10.3 | J23: 100 | K23: 1.1 | L23: =(AVERAGEA(E23:I23)/100)*(J23/100)*(K23) -> 0.1133 | M23: 0.01 | N23: =+L23*M23 -> 0.001133 | O23: =+N23/K23 -> 0.00103 | P23: Verificación
A24: TORNO | B24: 9 | C24: Tol. Verificar Paralelismo | D24: R | E24: 16.363636 | J24: 100 | K24: 1.1 | L24: =(AVERAGEA(E24:I24)/100)*(J24/100)*(K24) -> 0.18 | M24: 0.01 | N24: =+L24*M24 -> 0.0018 | O24: =+N24/K24 -> 0.0016363636 | P24: Verificación
A25: TORNO | B25: 10 | C25: Tol. Verificar diametro chaflan. 66,17+-0,1 | D25: R | E25: 16.363636 | J25: 100 | K25: 1.1 | L25: =(AVERAGEA(E25:I25)/100)*(J25/100)*(K25) -> 0.18 | M25: 0.01 | N25: =+L25*M25 -> 0.0018 | O25: =+N25/K25 -> 0.0016363636 | P25: Verificación
A26: TORNO | B26: 14 | C26: Desplazarse a zona de trabajo. 12 M -G-293= 0,197 | D26: R | E26: 17.909091 | J26: 100 | K26: 1.1 | L26: =(AVERAGEA(E26:I26)/100)*(J26/100)*(K26) -> 0.197 | M26: 0.04 | N26: =+L26*M26 -> 0.00788 | O26: =+N26/K26 -> 0.0071636364 | P26: Traslados.
A27: TALLADORA | B27: 15 | C27: TALLAR | D27: M | E27: 88 | J27: 100 | K27: 1 | L27: =(AVERAGEA(E27:I27)/100)*(J27/100)*(K27) -> 0.88 | M27: 1 | N27: =+L27*M27 -> 0.88 | O27: =+N27/K27 -> 0.88 | P27: Tiempo de máquina
A28: TALLADORA | B28: 16 | C28: Soplar con manguera de aire pieza a verificar. | D28: R | E28: 20 | F28: 24 | G28: 18 | H28: 18 | I28: 20 | J28: 105 | K28: 1.11 | L28: =(AVERAGEA(E28:I28)/100)*(J28/100)*(K28) -> 0.2331 | M28: 0.005 | N28: =+L28*M28 -> 0.0011655 | O28: =+N28/K28 -> 0.00105 | P28: Verificación
A29: TALLADORA | B29: 17 | C29: Tol. Verificar micro de platillos. | D29: R | E29: 16.909091 | J29: 100 | K29: 1.1 | L29: =(AVERAGEA(E29:I29)/100)*(J29/100)*(K29) -> 0.186 | M29: 0.005 | N29: =+L29*M29 -> 0.00093 | O29: =+N29/K29 -> 0.00084545455 | P29: Verificación
A30: TALLADORA | B30: 18 | C30: Revisar chaflan y rebaba | D30: R | E30: 10 | F30: 12 | J30: 110 | K30: 1.1 | L30: =(AVERAGEA(E30:I30)/100)*(J30/100)*(K30) -> 0.1331 | M30: 0.005 | N30: =+L30*M30 -> 0.0006655 | O30: =+N30/K30 -> 0.000605 | P30: Verificación
A31: BROCHADORA | B31: 19 | C31: BROCHAR-MARCAR-ROBOT | D31: M | E31: 80 | J31: 100 | K31: 1 | L31: =(AVERAGEA(E31:I31)/100)*(J31/100)*(K31) -> 0.8 | M31: 1 | N31: =+L31*M31 -> 0.8 | O31: =+N31/K31 -> 0.8 | P31: Tiempo de máquina
A32: BROCHADORA | B32: 20 | C32: Soplar con manguera de aire pieza a verificar. | D32: R | E32: 20 | F32: 24 | G32: 18 | H32: 18 | I32: 20 | J32: 105 | K32: 1.11 | L32: =(AVERAGEA(E32:I32)/100)*(J32/100)*(K32) -> 0.2331 | M32: 0.01 | N32: =+L32*M32 -> 0.002331 | O32: =+N32/K32 -> 0.0021 | P32: Verificación
A33: BROCHADORA | B33: 21 | C33: Tol. Ancho de chavetero 4,10±0,025 (ambos lados) F-25= 0,114 | D33: R | E33: 10.363636 | J33: 100 | K33: 1.1 | L33: =(AVERAGEA(E33:I33)/100)*(J33/100)*(K33) -> 0.114 | M33: 0.01 | N33: =+L33*M33 -> 0.00114 | O33: =+N33/K33 -> 0.0010363636 | P33: Verificación
A34: BROCHADORA | B34: 22 | C34: Tol. Verificar calibre verdaderaposición. | D34: R | E34: 35 | J34: 115 | K34: 1.12 | L34: =(AVERAGEA(E34:I34)/100)*(J34/100)*(K34) -> 0.4508 | M34: 0.01 | N34: =+L34*M34 -> 0.004508 | O34: =+N34/K34 -> 0.004025 | P34: Verificación
A35: BROCHADORA | B35: 23 | C35: Tol. Verificar profundidad de chavetero. 58,106(+0,174, +0,014) | D35: R | E35: 35 | J35: 115 | K35: 1.12 | L35: =(AVERAGEA(E35:I35)/100)*(J35/100)*(K35) -> 0.4508 | M35: 0.01 | N35: =+L35*M35 -> 0.004508 | O35: =+N35/K35 -> 0.004025 | P35: Verificación
A36: BROCHADORA | B36: 24 | C36: Tol. Verificar calibre de relación chavetero diente. ±0,15 (chaflán 50º abajo) | D36: R | E36: 30 | F36: 27 | G36: 34 | H36: 41 | I36: 24 | J36: 110 | K36: 1.11 | L36: =(AVERAGEA(E36:I36)/100)*(J36/100)*(K36) -> 0.380952 | M36: 0.01 | N36: =+L36*M36 -> 0.00380952 | O36: =+N36/K36 -> 0.003432 | P36: Verificación
A37: BROCHADORA | B37: 25 | C37: Tol. Verificación de referencia y posición de chavetero. | D37: R | E37: 10 | F37: 12 | J37: 110 | K37: 1.1 | L37: =(AVERAGEA(E37:I37)/100)*(J37/100)*(K37) -> 0.1331 | M37: 0.01 | N37: =+L37*M37 -> 0.001331 | O37: =+N37/K37 -> 0.00121 | P37: Verificación
A38: LAVADORA | B38: 26 | C38: Posicionarse en cinta de salida de lavadora. G-157= 0,086 | D38: R | E38: 7.8181818 | J38: 100 | K38: 1.1 | L38: =(AVERAGEA(E38:I38)/100)*(J38/100)*(K38) -> 0.086 | M38: 0.016666667 | N38: =+L38*M38 -> 0.0014333333 | O38: =+N38/K38 -> 0.0013030303 | P38: Traslados.
A39: LAVADORA | B39: 27 | C39: Posicionarse vacio en zona de trabajo. | D39: R | E39: 15.090909 | J39: 100 | K39: 1.1 | L39: =(AVERAGEA(E39:I39)/100)*(J39/100)*(K39) -> 0.166 | M39: 0.016666667 | N39: =+L39*M39 -> 0.0027666667 | O39: =+N39/K39 -> 0.0025151515 | P39: Traslados.
A40: CELULA | B40: 28 | C40: Piezas de cinta de salida a percha. | D40: R | E40: 41.666667 | F40: 38.333333 | G40: 40 | H40: 41.666667 | I40: 40 | J40: 125 | K40: 1.12 | L40: =(AVERAGEA(E40:I40)/100)*(J40/100)*(K40) -> 0.56466667 | M40: 0.016666667 | N40: =+L40*M40 -> 0.0094111111 | O40: =+N40/K40 -> 0.0084027778 | P40: Descarga
A41: VARIOS | B41: 29 | C41: Traslado a zona de trabajo, según porceda. (20m G-982= 0,323) | D41: R | E41: 29.363636 | J41: 100 | K41: 1.1 | L41: =(AVERAGEA(E41:I41)/100)*(J41/100)*(K41) -> 0.323 | M41: 0.04 | N41: =+L41*M41 -> 0.01292 | O41: =+N41/K41 -> 0.011745455 | P41: Traslados.
A42: TORNO | B42: 30 | C42: Limpiar torno con manguera de aire y gancho. | D42: D | E42: 56 | F42: 63 | G42: 49 | J42: 120 | K42: 1.12 | L42: =(AVERAGEA(E42:I42)/100)*(J42/100)*(K42) -> 0.75264 | M42: 0.016666667 | N42: =+L42*M42 -> 0.012544 | O42: =+N42/K42 -> 0.0112 | P42: Limpieza
A43: TORNO | B43: 31 | C43: Retirar viruta con gancho de cinta a contenedor en parte lateral | D43: R | E43: 280 | J43: 100 | K43: 1.12 | L43: =(AVERAGEA(E43:I43)/100)*(J43/100)*(K43) -> 3.136 | M43: 0.0071428571 | N43: =+L43*M43 -> 0.0224 | O43: =+N43/K43 -> 0.02 | P43: Limpieza
...

Sheet DZ133378-D
A2: REFERENCIA | B2: DZ133378 | C2: SECUENCIA DE EVENTOS | D2: Min. Std "D" | F2: =SUMIF(D16:D91,"D",N16:N91) -> 2.1118333 | G2: Min. Std "D"(P&F)/1,3 | I2: =SUMIF(D16:D91,"D",O16:O91)/1.3 -> 1.6166667 | J2: Ciclos posibles | L2: =480/I4 -> 88.615385 | M2: P&Fi | O2: =((F2+F3)/1.3-(I2+I3))*MIN(L2:L3) -> 1.4281043 | P2: Nº piezas autonomía
A3: CELULA | B3: 142D | D3: Min. Std "R" | F3: =SUMIF(D16:D91,"R",N16:N91) -> 0.11732868 | G3: Min. Std "R"(P&F)/1,3 | I3: =SUMIF(D16:D91,"R",O16:O91)/1.3 -> 0.081957586 | J3: Ciclos posibles Hombre | L3: =480/(F2/1.3+F3/1.3)/1.06 -> 264.08096 | M3: Piezas | O3: =IF((480-L4)<O2,L3,L2) -> 88.615385
A4: MC | B4: =SUMIF(D16:D74,"MC",N16:N74) -> 3.8 | D4: Ida | F4: =IF(1.1*(B4*1.08-F3/1.3)<0,0,1.1*(B4*1.08-F3/1.3)) -> 4.4151219 | G4: C.W | I4: =IF(F4=0,(F2/1.3+F3/1.3)*1.06,B4+I2) -> 5.4166667 | J4: Min.de trabajo manual | L4: =(I2+I3)*MIN(L2:L3)*1.06 -> 159.5557 | M4: Std | O4: =8*1.397*100/O3 -> 12.611806 | P4: 45
C6: Carga | D6: =SUMIFS($O$15:$O$99,$P$15:$P$99,C6) -> 0 | E6: =+D6*$O$3 -> 0
C7: Traslados. | D7: =SUMIFS($O$15:$O$99,$P$15:$P$99,C7) -> 0.017905455 | E7: =+D7*$O$3 -> 1.5866987
C8: Verificación | D8: =SUMIFS($O$15:$O$99,$P$15:$P$99,C8) -> 0.036492545 | E8: =+D8*$O$3 -> 3.233801
C9: Descarga | D9: =SUMIFS($O$15:$O$99,$P$15:$P$99,C9) -> 0.0021083333 | E9: =+D9*$O$3 -> 0.18683077
C10: Limpieza | D10: =SUMIFS($O$15:$O$99,$P$15:$P$99,C10) -> 0.055 | E10: =+D10*$O$3 -> 4.8738462
C11: Cambio de carga | D11: =SUMIFS($O$15:$O$99,$P$15:$P$99,C11) -> 0.034237013 | E11: =+D11*$O$3 -> 3.0339261
C12: Grafico | D12: =SUMIFS($O$15:$O$99,$P$15:$P$99,C12) -> 0.01475 | E12: =+D12*$O$3 -> 1.3070769
C13: CH | D13: =SUMIFS($O$15:$O$99,$P$15:$P$99,C13) -> 2.0477182 | E13: =+D13*$O$3 -> 181.45933
A15: MAQUINA | B15: Nº | C15: ELEMENTO | D15: TIPO | E15: T1 | F15: T2 | G15: T3 | H15: T4 | I15: T5 | J15: AC | K15: P&F | L15: MINUTOS STD | M15: OCURRENCIA | N15: MIN STD/CICLO | O15: MIN STD/CICLO (P&F) | P15: DESCRIPCIÓN
A16: TORNO | B16: 1 | C16: TORNEAR | D16: M | E16: 120 | J16: 100 | K16: 1 | L16: =(AVERAGEA(E16:I16)/100)*(J16/100)*(K16) -> 1.2 | M16: 1 | N16: =+L16*M16 -> 1.2 | O16: =+N16/K16 -> 1.2 | P16: Tiempo de máquina
A17: TORNO | B17: 2 | C17: Desplazarse vacio a zona de trabajo. | D17: R | E17: 15 | F17: 14 | G17: 14 | H17: 13 | I17: 14 | J17: 110 | K17: 1.1 | L17: =(AVERAGEA(E17:I17)/100)*(J17/100)*(K17) -> 0.1694 | M17: 0.04 | N17: =+L17*M17 -> 0.006776 | O17: =+N17/K17 -> 0.00616 | P17: Traslados.
A18: TORNO | B18: 3 | C18: Soplar con manguera de aire pieza a verificar. | D18: R | E18: 10 | F18: 12 | G18: 9 | H18: 9 | I18: 10 | J18: 110 | K18: 1.1 | L18: =(AVERAGEA(E18:I18)/100)*(J18/100)*(K18) -> 0.121 | M18: 0.005 | N18: =+L18*M18 -> 0.000605 | O18: =+N18/K18 -> 0.00055 | P18: Verificación
A19: TORNO | B19: 4 | C19: Tol. Verificar con calibre de herradura F-49-16-16120 Ø 144,75 ± 0,05 mm. F 14=0,081+0,046*2=0,173 | D19: R | E19: 15.727273 | J19: 100 | K19: 1.1 | L19: =(AVERAGEA(E19:I19)/100)*(J19/100)*(K19) -> 0.173 | M19: 0.005 | N19: =+L19*M19 -> 0.000865 | O19: =+N19/K19 -> 0.00078636364 | P19: Verificación
A20: TORNO | B20: 5 | C20: Tol. Verificar con calibre de herradura F-49-16-16121 36,2 ± 0,04 mm. | D20: R | E20: 15.727273 | J20: 100 | K20: 1.1 | L20: =(AVERAGEA(E20:I20)/100)*(J20/100)*(K20) -> 0.173 | M20: 0.005 | N20: =+L20*M20 -> 0.000865 | O20: =+N20/K20 -> 0.00078636364 | P20: Verificación
A21: TORNO | B21: 6 | C21: Tol. Verificar con tampon Marposs F-49-14-15200 Ø 87,649 (+0,01 / +0,04) mm. | D21: R | E21: 13 | F21: 12 | G21: 11 | H21: 14 | I21: 11 | J21: 115 | K21: 1.11 | L21: =(AVERAGEA(E21:I21)/100)*(J21/100)*(K21) -> 0.155733 | M21: 0.005 | N21: =+L21*M21 -> 0.000778665 | O21: =+N21/K21 -> 0.0007015 | P21: Verificación
A22: TORNO | B22: 7 | C22: Tol. Verificar con comparador con marmol | D22: R | E22: 25 | F22: 26 | G22: 24 | H22: 27 | I22: 25 | J22: 115 | K22: 1.1 | L22: =(AVERAGEA(E22:I22)/100)*(J22/100)*(K22) -> 0.32131 | M22: 0.005 | N22: =+L22*M22 -> 0.00160655 | O22: =+N22/K22 -> 0.0014605 | P22: Verificación
A23: TORNO | B23: 8 | C23: CH.-Abrir puertas y desplazar torreta a posición de trabajo | D23: D | E23: 92 | J23: 100 | K23: 1.1 | L23: =(AVERAGEA(E23:I23)/100)*(J23/100)*(K23) -> 1.012 | M23: 0.0016666667 | N23: =+L23*M23 -> 0.0016866667 | O23: =+N23/K23 -> 0.0015333333 | P23: CH
A24: TORNO | B24: 9 | C24: CH.-Cambio herramientas 2º cabezal, soplando herramienta y gitando torreta. | D24: D | E24: 930 | J24: 100 | K24: 1.1 | L24: =(AVERAGEA(E24:I24)/100)*(J24/100)*(K24) -> 10.23 | M24: 0.0016666667 | N24: =+L24*M24 -> 0.01705 | O24: =+N24/K24 -> 0.0155 | P24: CH
A25: TORNO | B25: 10 | C25: CH.- Cambio herramientas 1º cabezal, soplando herramienta y girando torreta. | D25: D | E25: 678 | J25: 100 | K25: 1.1 | L25: =(AVERAGEA(E25:I25)/100)*(J25/100)*(K25) -> 7.458 | M25: 0.0016666667 | N25: =+L25*M25 -> 0.01243 | O25: =+N25/K25 -> 0.0113 | P25: CH
A26: TORNO | B26: 11 | C26: CH.- Posicionar cabezales, cerrar puertas e iniciar programa de medición. | D26: D | E26: 70 | J26: 100 | K26: 1.1 | L26: =(AVERAGEA(E26:I26)/100)*(J26/100)*(K26) -> 0.77 | M26: 0.0016666667 | N26: =+L26*M26 -> 0.0012833333 | O26: =+N26/K26 -> 0.0011666667 | P26: CH
A27: TORNO | B27: 12 | C27: CH.-Medición de herramientas. | D27: D | E27: 250 | J27: 100 | K27: 1.1 | L27: =(AVERAGEA(E27:I27)/100)*(J27/100)*(K27) -> 2.75 | M27: 0.0016666667 | N27: =+L27*M27 -> 0.0045833333 | O27: =+N27/K27 -> 0.0041666667 | P27: CH
A28: TORNO | B28: 13 | C28: CH.- Hacer pieza y medir hasta corregir, | D28: D | E28: 780 | J28: 100 | K28: 1.1 | L28: =(AVERAGEA(E28:I28)/100)*(J28/100)*(K28) -> 8.58 | M28: 0.0016666667 | N28: =+L28*M28 -> 0.0143 | O28: =+N28/K28 -> 0.013 | P28: CH
A29: TORNO | B29: 14 | C29: Medir pieza en inicio de turno. MEDICIÓN=0,691 | D29: R | E29: 63.090909 | J29: 100 | K29: 1.1 | L29: =(AVERAGEA(E29:I29)/100)*(J29/100)*(K29) -> 0.694 | M29: 0.0016666667 | N29: =+L29*M29 -> 0.0011566667 | O29: =+N29/K29 -> 0.0010515152 | P29: CH
A30: TALLADORA | B30: 15 | C30: TALLAR | D30: MC | E30: 190 | J30: 100 | K30: 1 | L30: =(AVERAGEA(E30:I30)/100)*(J30/100)*(K30) -> 1.9 | M30: 1 | N30: =+L30*M30 -> 1.9 | O30: =+N30/K30 -> 1.9 | P30: Tiempo de máquina
A31: TALLADORA | B31: 16 | C31: Soplar con manguera de aire pieza a verificar. | D31: R | E31: 10 | F31: 12 | G31: 9 | H31: 9 | I31: 10 | J31: 110 | K31: 1.1 | L31: =(AVERAGEA(E31:I31)/100)*(J31/100)*(K31) -> 0.121 | M31: 0.01 | N31: =+L31*M31 -> 0.00121 | O31: =+N31/K31 -> 0.0011 | P31: Verificación
A32: TALLADORA | B32: 17 | C32: Tol. Verificar con micro de platillos F-49-35-00021 / 013 56,07 - 56,10 F-72=,114+,072=,186 | D32: R | E32: 16.909091 | J32: 100 | K32: 1.1 | L32: =(AVERAGEA(E32:I32)/100)*(J32/100)*(K32) -> 0.186 | M32: 0.01 | N32: =+L32*M32 -> 0.00186 | O32: =+N32/K32 -> 0.0016909091 | P32: Verificación
A33: REBERBADORA | B33: 18 | C33: REBARBAR | D33: M | E33: 80 | J33: 100 | K33: 1 | L33: =(AVERAGEA(E33:I33)/100)*(J33/100)*(K33) -> 0.8 | M33: 1 | N33: =+L33*M33 -> 0.8 | O33: =+N33/K33 -> 0.8 | P33: Tiempo de máquina
A34: BROCHADORA | B34: 19 | C34: BROCHAR | D34: M | E34: 55 | J34: 100 | K34: 1 | L34: =(AVERAGEA(E34:I34)/100)*(J34/100)*(K34) -> 0.55 | M34: 1 | N34: =+L34*M34 -> 0.55 | O34: =+N34/K34 -> 0.55 | P34: Tiempo de máquina
A35: BROCHADORA | B35: 20 | C35: Soplar con manguera de aire pieza a verificar. | D35: R | E35: 10 | F35: 12 | G35: 9 | H35: 9 | I35: 10 | J35: 110 | K35: 1.1 | L35: =(AVERAGEA(E35:I35)/100)*(J35/100)*(K35) -> 0.121 | M35: 0.01 | N35: =+L35*M35 -> 0.00121 | O35: =+N35/K35 -> 0.0011 | P35: Verificación
A36: BROCHADORA | B36: 21 | C36: Tol. Verificar con calibre de relación chavetero. | D36: R | E36: 30 | F36: 27 | G36: 34 | H36: 41 | I36: 24 | J36: 110 | K36: 1.11 | L36: =(AVERAGEA(E36:I36)/100)*(J36/100)*(K36) -> 0.380952 | M36: 0.01 | N36: =+L36*M36 -> 0.00380952 | O36: =+N36/K36 -> 0.003432 | P36: Verificación
A37: BROCHADORA | B37: 22 | C37: Tol. Verificar ancho de chavetero. F-25=0,114 | D37: R | E37: 10.363636 | J37: 100 | K37: 1.1 | L37: =(AVERAGEA(E37:I37)/100)*(J37/100)*(K37) -> 0.114 | M37: 0.01 | N37: =+L37*M37 -> 0.00114 | O37: =+N37/K37 -> 0.0010363636 | P37: Verificación
A38: BROCHADORA | B38: 23 | C38: Tol. Verificar con calibre profundidad chavetero. F-26=0,134 | D38: R | E38: 12.181818 | J38: 100 | K38: 1.1 | L38: =(AVERAGEA(E38:I38)/100)*(J38/100)*(K38) -> 0.134 | M38: 0.01 | N38: =+L38*M38 -> 0.00134 | O38: =+N38/K38 -> 0.0012181818 | P38: Verificación
A39: BROCHADORA | B39: 24 | C39: Tol verificas simetria chavetero interior | D39: R | E39: 10.363636 | J39: 100 | K39: 1.1 | L39: =(AVERAGEA(E39:I39)/100)*(J39/100)*(K39) -> 0.114 | M39: 0.01 | N39: =+L39*M39 -> 0.00114 | O39: =+N39/K39 -> 0.0010363636 | P39: Verificación
A40: BROCHADORA | B40: 25 | C40: Verificación visual. | D40: R | E40: 5 | F40: 6 | G40: 5 | H40: 6 | I40: 5 | J40: 110 | K40: 1.1 | L40: =(AVERAGEA(E40:I40)/100)*(J40/100)*(K40) -> 0.06534 | M40: 0.01 | N40: =+L40*M40 -> 0.0006534 | O40: =+N40/K40 -> 0.000594 | P40: Verificación
A41: CELULA | B41: 26 | C41: Pieza a bandeja de salida | D41: R | E41: 12 | F41: 10 | J41: 115 | K41: 1.1 | L41: =(AVERAGEA(E41:I41)/100)*(J41/100)*(K41) -> 0.13915 | M41: 0.016666667 | N41: =+L41*M41 -> 0.0023191667 | O41: =+N41/K41 -> 0.0021083333 | P41: Descarga
A42: VARIOS | B42: 27 | C42: Traslado a zona de trabajo, según porceda. (20m G-982= 0,323) | D42: R | E42: 29.363636 | J42: 100 | K42: 1.1 | L42: =(AVERAGEA(E42:I42)/100)*(J42/100)*(K42) -> 0.323 | M42: 0.04 | N42: =+L42*M42 -> 0.01292 | O42: =+N42/K42 -> 0.011745455 | P42: Traslados.
A43: CELULA | B43: 28 | C43: Limpieza de maquinas final del turno | D43: D | E43: 1000 | J43: 110 | K43: 1.1 | L43: =(AVERAGEA(E43:I43)/100)*(J43/100)*(K43) -> 12.1 | M43: 0.005 | N43: =+L43*M43 -> 0.0605 | O43: =+N43/K43 -> 0.055 | P43: Limpieza
...

Sheet COMBINADOR
A1: ESTUDIO COMBINACIÓN DE CÉLULAS
A2: REFERENCIA_1 | B2: =+'R120638-A'!B2 -> R120638 | C2: CELULA_1 | D2: =+'R120638-A'!B3 -> 142A | E2: REFERENCIA_2 | F2: =+'R120636-B'!B2 -> R120636 | G2: CELULA_2 | H2: =+'R120636-B'!B3 -> 142B | I2: REFERENCIA_3 | J2: =+'R544000-C'!B2 -> R544000 | K2: CELULA_3 | L2: =+'R544000-C'!B3 -> 142C | M2: REFERENCIA_4 | N2: =+'DZ133378-D'!B2 -> DZ133378 | O2: CELULA_4 | P2: =+'DZ133378-D'!B3 -> 142D
A4: T. MAQUINA | B4: =+'R120638-A'!B4 -> 1.06 | E4: T. MAQUINA | F4: =+'R120636-B'!B4 -> 1 | I4: T. MAQUINA | J4: =+'R544000-C'!B4 -> 0.93075 | M4: T. MAQUINA | N4: =+'DZ133378-D'!B4 -> 3.8
A6: Min. Std "D" | B6: =+'R120638-A'!F2 -> 2.0259251 | C6: Min. Std "R" | D6: =+'R120638-A'!F3 -> 0.13205418 | E6: Min. Std "D" | F6: =+'R120636-B'!F2 -> 2.0194901 | G6: Min. Std "R" | H6: =+'R120636-B'!F3 -> 0.13410452 | I6: Min. Std "D" | J6: =+'R544000-C'!F2 -> 1.1154582 | K6: Min. Std "R" | L6: =+'R544000-C'!F3 -> 0.16197157 | M6: Min. Std "D" | N6: =+'DZ133378-D'!F2 -> 2.1118333 | O6: Min. Std "R" | P6: =+'DZ133378-D'!F3 -> 0.11732868
A7: Ida | B7: =+'R120638-A'!F4 -> 1.1475418 | C7: C.W.I | D7: =+'R120638-A'!I4 -> 2.6165413 | E7: Ida | F7: =+'R120636-B'!F4 -> 1.0745269 | G7: C.W.I | H7: =+'R120636-B'!I4 -> 2.5520413 | I7: Ida | J7: =+'R544000-C'!F4 -> 0.96867814 | K7: C.W.I | L7: =+'R544000-C'!I4 -> 1.7802978 | M7: Ida | N7: =+'DZ133378-D'!F4 -> 4.4151219 | O7: C.W.I | P7: =+'DZ133378-D'!I4 -> 5.4166667
A8: Ciclos Posibles | B8: =+'R120638-A'!L2 -> 183.44828 | C8: Ciclos Posibles H. | D8: =+'R120638-A'!L3 -> 272.79189 | E8: Ciclos Posibles | F8: =+'R120636-B'!L2 -> 188.08473 | G8: Ciclos Posibles H. | H8: =+'R120636-B'!L3 -> 273.34729 | I8: Ciclos Posibles | J8: =+'R544000-C'!L2 -> 269.61782 | K8: Ciclos Posibles H. | L8: =+'R544000-C'!L3 -> 460.83102 | M8: Ciclos Posibles | N8: =+'DZ133378-D'!L2 -> 88.615385 | O8: Ciclos Posibles H. | P8: =+'DZ133378-D'!L3 -> 264.08096
A9: Min.Trabajo Manual | B9: =+'R120638-A'!L4 -> 320.44252 | C9: P&Fi | D9: =+'R120638-A'!O2 -> 2.2169535 | E9: Min.Trabajo Manual | F9: =+'R120636-B'!L4 -> 327.91414 | G9: P&Fi | H9: =+'R120636-B'!O2 -> 2.2303083 | I9: Min.Trabajo Manual | J9: =+'R544000-C'!L4 -> 274.99014 | K9: P&Fi | L9: =+'R544000-C'!O2 -> 5.5121223 | M9: Min.Trabajo Manual | N9: =+'DZ133378-D'!L4 -> 159.5557 | O9: P&Fi | P9: =+'DZ133378-D'!O2 -> 1.4281043
A10: Piezas ind. | B10: =+'R120638-A'!O3 -> 183.44828 | C10: Std. Ind | D10: =+'R120638-A'!O4 -> 6.0921804 | E10: Piezas ind. | F10: =+'R120636-B'!O3 -> 188.08473 | G10: Std. Ind | H10: =+'R120636-B'!O4 -> 5.9420029 | I10: Piezas ind. | J10: =+'R544000-C'!O3 -> 269.61782 | K10: Std. Ind | L10: =+'R544000-C'!O4 -> 4.1451266 | M10: Piezas ind. | N10: =+'DZ133378-D'!O3 -> 88.615385 | O10: Std. Ind | P10: =+'DZ133378-D'!O4 -> 12.611806
A12: Ida Combinado | B12: =IF((1.1*(B4*1.08-(D6+F6*H17+H6*H17+J6*L17+L6*L17+N6*P17+P6*P17)/1.3))>0,(1.1*(B4*1.08-(D6*+F6*H17+H6*H17+J6*L17+L6*L17+N6*P17+P6*P17)/1.3)),0) -> 0 | C12: C.W.C | D12: =IF(B12=0,(B6/1.3+D6/1.3+F6*H17/1.3+H6*H17/1.3+J6*L17/1.3+L6*L17/1.3+N6*P17/1.3+P6*P17/1.3)*1.06,B4+'R120638-A'!I2) -> 4.8807824 | E12: Ida Combinado | F12: =IF((1.1*(F4*1.08-(D6*D17+B6*D17+H6+J6*L17+L6*L17+N6*P17+P6*P17)/1.3))>0,(1.1*(F4*1.08-(D6*D17+B6*D17+H6+J6*L17+L6*L17+N6*P17+P6*P17)/1.3)),0) -> 0 | G12: C.W.C | H12: =IF(F12=0,(B6*D17/1.3+D6*D17/1.3+F6/1.3+H6/1.3+J6*L17/1.3+L6*L17/1.3+N6*P17/1.3+P6*P17/1.3)*1.06,F4+'R120636-B'!I2) -> 4.787833 | I12: Ida Combinado | J12: =IF((1.1*(J4*1.08-(B6*D17+D6*D17+F6*H17+H6*H17+L6+N6*P17+P6*P17)/1.3))>0,(1.1*(J4*1.08-(B6*D17+D6*D17+F6*H17+H6*H17+J6+N6*P17+P6*P17)/1.3)),0) -> 0 | K12: C.W.C | L12: =IF(J12=0,(B6*D17/1.3+D6*D17/1.3+F6*H17/1.3+H6*H17/1.3+J6/1.3+L6/1.3+N6*P17/1.3+P6*P17/1.3)*1.06,J4+'R544000-C'!I2) -> 4.6662295 | M12: Ida Combinado | N12: =IF((1.1*(N4*1.08-(B6*D17+D6*D17+F6*H17+H6*H17+J6*L17+L6*L17+P6)/1.3))>0,(1.1*(N4*1.08-(B6*D17+D6*D17+F6*H17+H6*H17+J6*L17+L6*L17+P6)/1.3)),0) -> 0.034806614 | O12: C.W.C | P12: =IF(N12=0,(B6*D17/1.3+D6*D17/1.3+F6*H17/1.3+H6*H17/1.3+J6/1.3+L6/1.3+N6*P17/1.3+P6*P17/1.3)*1.06,N4+'DZ133378-D'!I2) -> 5.4166667
A13: Ciclos Posibles C | B13: =480/D12 -> 98.344888 | C13: Ciclos Posibles H. | E13: Ciclos Posibles C | F13: =480/H12 -> 100.25412 | G13: Ciclos Posibles H. | I13: Ciclos Posibles C | J13: =480/L12 -> 102.86678 | K13: Ciclos Posibles H. | M13: Ciclos Posibles C | N13: =480/P12 -> 88.615385 | O13: Ciclos Posibles H.
A14: Tª Trabajo C | B14: =('R120638-A'!I2+'R120638-A'!I3)*1.06*COMBINADOR!B13 -> 171.78621 | C14: P&Fc | D14: =(('R120638-A'!F2+'R120638-A'!F3)/1.3-('R120638-A'!I2+'R120638-A'!I3))*COMBINADOR!B13 -> 1.1884878 | E14: Tª Trabajo C | F14: =('R120636-B'!I2+'R120636-B'!I3)*1.06*COMBINADOR!F13 -> 174.78689 | G14: P&Fc | H14: =(('R120636-B'!F2+'R120636-B'!F3)/1.3-('R120636-B'!I2+'R120636-B'!I3))*COMBINADOR!F13 -> 1.1888132 | I14: Tª Trabajo C | J14: =('R544000-C'!I2+'R544000-C'!I3)*1.06*COMBINADOR!J13 -> 104.91647 | K14: P&Fc | L14: =(('R544000-C'!F2+'R544000-C'!F3)/1.3-('R544000-C'!I2+'R544000-C'!I3))*COMBINADOR!J13 -> 2.1030296 | M14: Tª Trabajo C | N14: =('DZ133378-D'!I2+'DZ133378-D'!I3)*1.06*COMBINADOR!N13 -> 159.5557 | O14: P&Fc | P14: =(('DZ133378-D'!F2+'DZ133378-D'!F3)/1.3-('DZ133378-D'!I2+'DZ133378-D'!I3))*COMBINADOR!N13 -> 1.4281043
A15: Piezas Com. | B15: =+B13 -> 98.344888 | C15: Std Comb. | D15: =8/4*1.397*100/B15 -> 2.8410221 | E15: Piezas Com. | F15: =+F13 -> 100.25412 | G15: Std Comb. | H15: =8/4*1.397*100/F15 -> 2.7869178 | I15: Piezas Com. | J15: =+J13 -> 102.86678 | K15: Std Comb. | L15: =8/4*1.397*100/J15 -> 2.7161344 | M15: Piezas Com. | N15: =+N13 -> 88.615385 | O15: Std Comb. | P15: =8/4*1.397*100/N15 -> 3.1529514
A17: Perdida Vs Ind | B17: =1-B15/B10 -> 0.46390945 | C17: Ratio | D17: =MIN(B4,F4,J4,N4)/B4 -> 0.87806604 | E17: Perdida Vs Ind | F17: =1-F15/F10 -> 0.46697361 | G17: Ratio | H17: =MIN(B4,F4,J4,N2)/F4 -> 0.93075 | I17: Perdida Vs Ind | J17: =1-J15/J10 -> 0.61847188 | K17: Ratio | L17: =MIN(B4,F4,J4,N4)/J4 -> 1 | M17: Perdida Vs Ind | N17: =1-N15/N10 -> 0 | O17: Ratio | P17: =MIN(B4,F4,J4,N4)/N4 -> 0.24493421
A19: Minutos manuales hombre | B19: =IF((B14+F14+J14+N14)>480,480,(B14+F14+J14+N14)) -> 480 | D19: Minutos libres hombre. | E19: =480-B19 -> 0 | G19: P&F Comb. | H19: =+D14+H14+L14+P14 -> 5.9084349

Sheet ENTREGABLE NEW
B3: REFERENCIA 1 | C3: =+'R120638-A'!B2 -> R120638 | D3: =+'R120638-A'!B3 -> 142A | F3: FECHA | G3: 45910
B4: REFERENCIA 2 | C4: =+'R120636-B'!B2 -> R120636 | D4: =+'R120636-B'!B3 -> 142B | F4: OPERARIO
B5: REFERENCIA 3 | C5: =+'R544000-C'!B2 -> R544000 | D5: =+'R544000-C'!B3 -> 142C | F5: INGENIERO | N5: Std de trabajo John Deere Ibérica
B6: REFERENCIA 4 | C6: =+'DZ133378-D'!B2 -> DZ133378 | D6: =+'DZ133378-D'!B3 -> 142D
N7: =+G3 -> 45910
L8: =+G3 -> 45910 | N8: REFERENCIA 1 | O8: REFERENCIA 2 | P8: REFERENCIA 3 | Q8: REFERENCIA 4 | R8: REFERENCIA 1
A9: ELEMENTO | B9: CÉLULA | C9: FASE | D9: DESCRIPCIÓN DE ELEMTOS | J9: TIPO | K9: OCURRENCIA | L9: MIN STD/CICLO | N9: =+C3 -> R120638 | O9: =+C4 -> R120636 | P9: =+C5 -> R544000 | Q9: =+C6 -> DZ133378 | R9: Min. Std "D" | T9: =+'R120638-A'!F2 -> 2.0259251
A10: 1 | B10: =$D$3 -> 142A | C10: =+'R120638-A'!A16 -> TORNO | D10: =+'R120638-A'!C16 -> TORNEAR | J10: =+'R120638-A'!D16 -> M | K10: =+'R120638-A'!M16 -> 1 | L10: =+'R120638-A'!N16 -> 0.9 | N10: STD 1 | O10: STD 2 | P10: STD 3 | Q10: STD 4 | R10: Min. Std "R" | T10: =+'R120638-A'!F3 -> 0.13205418
A11: 2 | B11: =$D$3 -> 142A | C11: =+'R120638-A'!#REF! -> #REF! | D11: =+'R120638-A'!#REF! -> #REF! | J11: =+'R120638-A'!#REF! -> #REF! | K11: =+'R120638-A'!#REF! -> #REF! | L11: =+'R120638-A'!#REF! -> #REF! | N11: =+COMBINADOR!D15 -> 2.8410221 | O11: =+COMBINADOR!H15 -> 2.7869178 | P11: =+COMBINADOR!L15 -> 2.7161344 | Q11: =+COMBINADOR!P15 -> 3.1529514 | R11: Ida | T11: =+'R120638-A'!F4 -> 1.1475418
A12: 3 | B12: =$D$3 -> 142A | C12: =+'R120638-A'!#REF! -> #REF! | D12: =+'R120638-A'!#REF! -> #REF! | J12: =+'R120638-A'!#REF! -> #REF! | K12: =+'R120638-A'!#REF! -> #REF! | L12: =+'R120638-A'!#REF! -> #REF! | N12: Pzas mínimas 1 | O12: Pzas mínimas 2 | P12: Pzas mínimas 3 | Q12: Pzas mínimas 4 | R12: Maquina Control. | T12: =+'R120638-A'!B4 -> 1.06
A13: 4 | B13: =$D$3 -> 142A | C13: =+'R120638-A'!#REF! -> #REF! | D13: =+'R120638-A'!#REF! -> #REF! | J13: =+'R120638-A'!#REF! -> #REF! | K13: =+'R120638-A'!#REF! -> #REF! | L13: =+'R120638-A'!#REF! -> #REF! | N13: =+COMBINADOR!B15 -> 98.344888 | O13: =+COMBINADOR!F15 -> 100.25412 | P13: =+COMBINADOR!J15 -> 102.86678 | Q13: =+COMBINADOR!N15 -> 88.615385 | R13: Ida Combinado. | T13: =+COMBINADOR!B12 -> 0
A14: 5 | B14: =$D$3 -> 142A | C14: =+'R120638-A'!#REF! -> #REF! | D14: =+'R120638-A'!#REF! -> #REF! | J14: =+'R120638-A'!#REF! -> #REF! | K14: =+'R120638-A'!#REF! -> #REF! | L14: =+'R120638-A'!#REF! -> #REF! | N14: Descripción. | R14: REFERENCIA 2
A15: 6 | B15: =$D$3 -> 142A | C15: =+'R120638-A'!#REF! -> #REF! | D15: =+'R120638-A'!#REF! -> #REF! | J15: =+'R120638-A'!#REF! -> #REF! | K15: =+'R120638-A'!#REF! -> #REF! | L15: =+'R120638-A'!#REF! -> #REF! | R15: Min. Std "D" | T15: =+'R120636-B'!F2 -> 2.0194901
A16: 7 | B16: =$D$3 -> 142A | C16: =+'R120638-A'!#REF! -> #REF! | D16: =+'R120638-A'!#REF! -> #REF! | J16: =+'R120638-A'!#REF! -> #REF! | K16: =+'R120638-A'!#REF! -> #REF! | L16: =+'R120638-A'!#REF! -> #REF! | N16: Razón de cambio. | R16: Min. Std "R" | T16: =+'R120636-B'!F3 -> 0.13410452
A17: 8 | B17: =$D$3 -> 142A | C17: =+'R120638-A'!#REF! -> #REF! | D17: =+'R120638-A'!#REF! -> #REF! | J17: =+'R120638-A'!#REF! -> #REF! | K17: =+'R120638-A'!#REF! -> #REF! | L17: =+'R120638-A'!#REF! -> #REF! | R17: Ida | T17: =+'R120636-B'!F4 -> 1.0745269
A18: 9 | B18: =$D$3 -> 142A | C18: =+'R120638-A'!#REF! -> #REF! | D18: =+'R120638-A'!#REF! -> #REF! | J18: =+'R120638-A'!#REF! -> #REF! | K18: =+'R120638-A'!#REF! -> #REF! | L18: =+'R120638-A'!#REF! -> #REF! | N18: Observaciones. | P18: Zona de trabajo. | R18: Maquina Control. | T18: =+'R120636-B'!B4 -> 1
A19: 10 | B19: =$D$3 -> 142A | C19: =+'R120638-A'!A17 -> TORNO | D19: =+'R120638-A'!C17 -> CH.-Abrir puertas y desplazar torreta a posición de trabajo | J19: =+'R120638-A'!D17 -> D | K19: 0.0005 | L19: =+'R120638-A'!N17 -> 0.000506 | R19: Ida Combinado. | T19: =+COMBINADOR!F12 -> 0
A20: 11 | B20: =$D$3 -> 142A | C20: =+'R120638-A'!A18 -> TORNO | D20: =+'R120638-A'!C18 -> CH.-Cambio (12) herramientas 2º cabezal, soplando herramienta y gitando torreta. | J20: =+'R120638-A'!D18 -> D | K20: 0.0005 | L20: =+'R120638-A'!N18 -> 0.005115 | R20: REFERENCIA 3
A21: 12 | B21: =$D$3 -> 142A | C21: =+'R120638-A'!A19 -> TORNO | D21: =+'R120638-A'!C19 -> CH.- Cambio (12) herramientas 1º cabezal, soplando herramienta y girando torreta. | J21: =+'R120638-A'!D19 -> D | K21: 0.0005 | L21: =+'R120638-A'!N19 -> 0.003729 | R21: Min. Std "D" | T21: =+COMBINADOR!J6 -> 1.1154582
A22: 13 | B22: =$D$3 -> 142A | C22: =+'R120638-A'!A20 -> TORNO | D22: =+'R120638-A'!C20 -> CH.- Posicionar cabezales, cerrar puertas e iniciar programa de medición. | J22: =+'R120638-A'!D20 -> D | K22: 0.0005 | L22: =+'R120638-A'!N20 -> 0.0005005 | R22: Min. Std "R" | T22: =+COMBINADOR!L6 -> 0.16197157
A23: 14 | B23: =$D$3 -> 142A | C23: =+'R120638-A'!A21 -> TORNO | D23: =+'R120638-A'!C21 -> CH.-Medición de herramientas. | J23: =+'R120638-A'!D21 -> D | K23: 0.0005 | L23: =+'R120638-A'!N21 -> 0.001375 | R23: Ida | T23: =+COMBINADOR!J7 -> 0.96867814
A24: 15 | B24: =$D$3 -> 142A | C24: =+'R120638-A'!A22 -> TORNO | D24: =+'R120638-A'!C22 -> CH.- Hacer pieza y medir hasta corregir, | J24: =+'R120638-A'!D22 -> D | K24: 0.0005 | L24: =+'R120638-A'!N22 -> 0.00429 | R24: Maquina Control. | T24: =+COMBINADOR!J4 -> 0.93075
A25: 16 | B25: =$D$3 -> 142A | C25: =+'R120638-A'!A23 -> TORNO | D25: =+'R120638-A'!C23 -> CH.- Llenado de cinta de paso torno-talladora. | J25: =+'R120638-A'!D23 -> D | K25: 0.0005 | L25: =+'R120638-A'!N23 -> 0.0060775 | R25: Ida Combinado. | T25: =+COMBINADOR!J12 -> 0
A26: 17 | B26: =$D$3 -> 142A | C26: =+'R120638-A'!A24 -> TORNO | D26: =+'R120638-A'!C24 -> CH.-Rearmar talladora. | J26: =+'R120638-A'!D24 -> D | K26: 0.0005 | L26: =+'R120638-A'!N24 -> 0.0003575 | R26: REFERENCIA 4
A27: 18 | B27: =$D$3 -> 142A | C27: =+'R120638-A'!A25 -> TORNO | D27: =+'R120638-A'!C25 -> Medir pieza en inicio de turno. MEDICIÓN=0,691 | J27: =+'R120638-A'!D25 -> R | K27: =+'R120638-A'!M25 -> 0.0025 | L27: =+'R120638-A'!N25 -> 0.001735 | R27: Min. Std "D" | T27: =+COMBINADOR!L6 -> 0.16197157
A28: 19 | B28: =$D$3 -> 142A | C28: =+'R120638-A'!A26 -> TALLADORA | D28: =+'R120638-A'!C26 -> TALLAR | J28: =+'R120638-A'!D26 -> M | K28: =+'R120638-A'!M26 -> 1 | L28: =+'R120638-A'!N26 -> 0.95 | R28: Min. Std "R" | T28: =+COMBINADOR!P6 -> 0.11732868
A29: 20 | B29: =$D$3 -> 142A | C29: =+'R120638-A'!A27 -> TALLADORA | D29: =+'R120638-A'!C27 -> Soplar con manguera de aire pieza a verificar. | J29: =+'R120638-A'!D27 -> R | K29: =+'R120638-A'!M27 -> 0.005 | L29: =+'R120638-A'!N27 -> 0.000924 | N29: Piezas por ciclo. | Q29: 1 | R29: Ida | T29: =+COMBINADOR!N7 -> 4.4151219
A30: 21 | B30: =$D$3 -> 142A | C30: =+'R120638-A'!A28 -> TALLADORA | D30: =+'R120638-A'!C28 -> Tol. Verificar con micro de platillos. 36,07-36,04. F-72=,114+,072=,186 | J30: =+'R120638-A'!D28 -> R | K30: =+'R120638-A'!M28 -> 0.005 | L30: =+'R120638-A'!N28 -> 0.00093 | N30: El Método aprobado es el que se detalla en este formulario,ningún cambio de método puede ser hecho por el operario sin contar con la aprobación de la Compañía indicada por la emisión de una revisión. | R30: Maquina Control. | T30: =+COMBINADOR!N4 -> 3.8
A31: 22 | B31: =$D$3 -> 142A | C31: =+'R120638-A'!A29 -> MARCADORA | D31: =+'R120638-A'!C29 -> MARCAR | J31: =+'R120638-A'!D29 -> M | K31: =+'R120638-A'!M29 -> 1 | L31: =+'R120638-A'!N29 -> 0.5 | R31: Ida Combinado. | T31: =+COMBINADOR!N12 -> 0.034806614
A32: 23 | B32: =$D$3 -> 142A | C32: =+'R120638-A'!A30 -> AFEITADORA | D32: =+'R120638-A'!C30 -> AFEITAR | J32: =+'R120638-A'!D30 -> MC | K32: =+'R120638-A'!M30 -> 1 | L32: =+'R120638-A'!N30 -> 1.06
A33: 24 | B33: =$D$3 -> 142A | C33: =+'R120638-A'!A31 -> AFEITADORA | D33: =+'R120638-A'!C31 -> Soplar con manguera de aire pieza a verificar. | J33: =+'R120638-A'!D31 -> R | K33: =+'R120638-A'!M31 -> 0.005 | L33: =+'R120638-A'!N31 -> 0.000924
A34: 25 | B34: =$D$3 -> 142A | C34: =+'R120638-A'!A32 -> AFEITADORA | D34: =+'R120638-A'!C32 -> Tol. Verificar con micro de platillos. 36,00-35,97. F-72=,114+,072=,186 | J34: =+'R120638-A'!D32 -> R | K34: =+'R120638-A'!M32 -> 0.005 | L34: =+'R120638-A'!N32 -> 0.00093
A35: 26 | B35: =$D$3 -> 142A | C35: =+'R120638-A'!A33 -> AFEITADORA | D35: =+'R120638-A'!C33 -> Tol. Verificar visual rebaba y chaflan | J35: =+'R120638-A'!D33 -> R | K35: =+'R120638-A'!M33 -> 0.005 | L35: =+'R120638-A'!N33 -> 0.00093
A36: 27 | B36: =$D$3 -> 142A | C36: =+'R120638-A'!A34 -> AFEITADORA | D36: =+'R120638-A'!C34 -> Tol. Verificación visual de referencia. | J36: =+'R120638-A'!D34 -> R | K36: =+'R120638-A'!M34 -> 0.005 | L36: =+'R120638-A'!N34 -> 0.00033
A37: 28 | B37: =$D$3 -> 142A | C37: =+'R120638-A'!A35 -> CELULA | D37: =+'R120638-A'!C35 -> Descargar piezas de carril de afeitadora a percha. | J37: =+'R120638-A'!D35 -> R | K37: =+'R120638-A'!M35 -> 0.016666667 | L37: =+'R120638-A'!N35 -> 0.076636
A38: 29 | B38: =$D$3 -> 142A | C38: =+'R120638-A'!A36 -> AFEITADORA | D38: =+'R120638-A'!C36 -> Posicionarse vacio en bandeja de piezas sin procesar. 10m G958=0,166 | J38: =+'R120638-A'!D36 -> R | K38: =+'R120638-A'!M36 -> 0.016666667 | L38: =+'R120638-A'!N36 -> 0.0027666667
A39: 30 | B39: =$D$3 -> 142A | C39: =+'R120638-A'!A37 -> VARIOS | D39: =+'R120638-A'!C37 -> Traslado a zona de trabajo, según porceda. (20m G-982= 0,323) | J39: =+'R120638-A'!D37 -> R | K39: =+'R120638-A'!M37 -> 0.04 | L39: =+'R120638-A'!N37 -> 0.01292
A40: 31 | B40: =$D$3 -> 142A | C40: =+'R120638-A'!A38 -> CELULA | D40: =+'R120638-A'!C38 -> Limpiar virutas de torno con manguera de aire y gancho. | J40: =+'R120638-A'!D38 -> D | K40: =+'R120638-A'!M38 -> 0.0025 | L40: =+'R120638-A'!N38 -> 0.0018816
A41: 32 | B41: =$D$3 -> 142A | C41: =+'R120638-A'!A39 -> CELULA | D41: =+'R120638-A'!C39 -> Limpiar virutas de talladora con manguera de aire. | J41: =+'R120638-A'!D39 -> D | K41: =+'R120638-A'!M39 -> 0.0025 | L41: =+'R120638-A'!N39 -> 0.002093
A42: 33 | B42: =$D$3 -> 142A | C42: =+'R120638-A'!A40 -> VARIOS | D42: =+'R120638-A'!C40 -> Girar bandeja de piezas 180º | J42: =+'R120638-A'!D40 -> R | K42: =+'R120638-A'!M40 -> 0.0026041667 | L42: =+'R120638-A'!N40 -> 0.00057291667
...

Sheet MM
B4: CAMBIO DE CARGA PP | M4: CAMBIO DE CARGA PSP &PP
C5: DESCRIPCIÓN | E5: Mtrs. | F5: Tipo | G5: Min.Std. | H5: Valor | K5: Tot.Min.Std. | N5: DESCRIPCIÓN | P5: Mtrs. | Q5: Tipo | R5: Min. | S5: Valor | V5: Tot.Min.Std.
B6: 1 | C6: Ir a por carretilla a zona de aparcamiento. | E6: 50 | F6: Var. | G6: =0.076+(E6-3.05)/0.305*0.005 -> 0.84567213 | H6: "G" datos Std | K6: =G6 -> 0.84567213 | M6: 1 | N6: Ir a por carretilla a zona de aparcamiento. | P6: 50 | Q6: Var. | R6: =0.076+(P6-3.05)/0.305*0.005 -> 0.84567213 | S6: "G" datos Std | V6: =R6 -> 0.84567213
B7: 2 | C7: Volver a maquina con carretilla. | E7: 50 | F7: Var. | G7: =(1/(7000/60))*1.3*1.1 -> 0.012257143 | H7: Min. Std./Mtr | K7: =G7*E7 -> 0.61285714 | M7: 2 | N7: Volver a maquina con carretilla. | P7: 50 | Q7: Var. | R7: =(1/(7000/60))*1.3*1.1 -> 0.012257143 | S7: Min. Std./Mtr | V7: =R7*P7 -> 0.61285714
B8: 3 | C8: Posicionar carretilla en la bandeja y retirar. | F8: Cte. | G8: 0.491 | H8: Min. Std. | K8: =G8 -> 0.491 | M8: 3 | N8: Posicionar carretilla en la bandeja vacia y retirar. | Q8: Cte. | R8: 0.491 | S8: Min. Std. | V8: =R8 -> 0.491
B9: 4 | C9: Llevar bandeja llena a zona de almacen. | E9: 100 | F9: Var. | G9: 0.024 | H9: Min. Std./Mtr | K9: =G9*E9 -> 2.4 | M9: 4 | N9: Llevar bandeja vacia a zona de salida | P9: 20 | Q9: Var. | R9: 0.024 | S9: Min. Std./Mtr | V9: =R9*P9 -> 0.48
B10: 5 | C10: Colocar bandeja y bajar. | F10: Cte. | G10: 0.254 | H10: Min. Std. | K10: =G10 -> 0.254 | M10: 5 | N10: Colocar bandeja en zona de salida y bajar. | Q10: Cte. | R10: 0.254 | S10: Min. Std. | V10: =R10 -> 0.254
B11: 6 | C11: Sacar carretilla. | F11: Cte. | G11: 0.254 | H11: Min. Std. | K11: =G11 -> 0.254 | M11: 6 | N11: Posicionar carretilla en la bandeja llena y retirar. | Q11: Cte. | R11: 0.491 | S11: Min. Std. | V11: =R11 -> 0.491
B12: 7 | C12: Desplazarse con carretilla a zona de bandejas vacias | E12: 100 | F12: Var. | G12: =(1/(7000/60))*1.3*1.1 -> 0.012257143 | H12: Min. Std./Mtr | K12: =G12*E12 -> 1.2257143 | M12: 7 | N12: Llevar bandeja llena a zona de almacen. | P12: 100 | Q12: Var. | R12: 0.024 | S12: Min. Std./Mtr | V12: =R12*P12 -> 2.4
B13: 8 | C13: Posicionar carretilla en bandeja y elevar. | F13: Cte. | G13: 0.491 | H13: Min. Std. | K13: =G13 -> 0.491 | M13: 8 | N13: Colocar bandeja y bajar. | Q13: Cte. | R13: 0.254 | S13: Min. Std. | V13: =R13 -> 0.254
B14: 9 | C14: Llevar bandeja en zona de descarga. | E14: 100 | F14: Var. | G14: 0.024 | H14: Min. Std./Mtr | K14: =G14*E14 -> 2.4 | M14: 9 | N14: Sacar carretilla. | Q14: Cte. | R14: 0.189 | S14: Min. Std. | V14: =R14 -> 0.189
B15: 10 | C15: Sacar carretilla. | F15: Cte. | G15: 0.254 | H15: Min. Std. | K15: =G15 -> 0.254 | M15: 10 | N15: Desplazarse con carretilla a zona de bandejas con piezas. | P15: 100 | Q15: Var. | R15: =(1/(7000/60))*1.3*1.1 -> 0.012257143 | S15: Min. Std./Mtr | V15: =R15*P15 -> 1.2257143
B16: 11 | C16: Llevar carretilla a zona de aparcamiento. | E16: 50 | F16: Var. | G16: =(1/(7000/60))*1.3*1.1 -> 0.012257143 | H16: Min. Std./Mtr | K16: =G16*E16 -> 0.61285714 | M16: 11 | N16: Posicionar carretilla en bandeja y elevar. | Q16: Cte. | R16: 0.491 | S16: Min. Std. | V16: =R16 -> 0.491
